Workbook

Sheet Feature List
A1: MRI ERP Implementation Taxonomy — Feature List & QA Tracker
A2: Existing functionality (from source) + items folded in from the DevOps board. DevOps Ref maps each feature to its story. See Comparison sheet for the full reconciliation.
A4: # | B4: Category | C4: Feature | D4: Description | E4: Where it lives | F4: Source | G4: Dev Status | H4: Tested? | I4: QA Status | J4: DevOps Ref | K4: QA Notes
A5: 1 | B5: Views & Navigation | C5: Three top-level views | D5: Switch between Business Process (default), System (MRI PMX), and Mapping (coverage matrix) views via the view switcher. | E5: main.js · switchView() | F5: Existing | G5: Done | H5: No | I5: Not Tested | J5: 3216
A6: 2 | B6: Views & Navigation | C6: View-specific hints | D6: Contextual sub-heading explains what each view shows as you switch. | E6: main.js · VIEW_HINTS | F6: Existing | G6: Done | H6: No | I6: Not Tested | J6: 3278
A7: 3 | B7: Views & Navigation | C7: Module tab bar | D7: Tab per MRI module in the System view; active tab is highlighted; clicking switches modules. | E7: main.js · switchTab() / index.html | F7: Existing | G7: Done | H7: Yes | I7: Pass | J7: 3218, 3228 | K7: Tested and closed 15 Sept 2026.
A8: 4 | B8: Views & Navigation | C8: Value-stream tab bar | D8: Tab per business value stream in the Business view, with supporting streams visually marked. | E8: businessView.js · renderBusinessTabs() | F8: Existing | G8: Done | H8: No | I8: Not Tested | J8: 3221
A9: 5 | B9: Views & Navigation | C9: Detail panel | D9: Right-side slide-in panel opens on any process/sub click, showing full detail for that item. | E9: panel.js / businessView.js | F9: Existing | G9: Done | H9: No | I9: Not Tested | J9: 3217
A10: 6 | B10: Views & Navigation | C10: Expand / collapse sub-processes | D10: Processes with sub-processes can be expanded individually or all at once (System view). | E10: main.js · toggleExpandAll() | F10: Existing | G10: Done | H10: No | I10: Not Tested | J10: 3219
A11: 7 | B11: Views & Navigation | C11: Keyboard shortcuts | D11: Esc closes any modal/panel; Enter confirms add dialogs; Ctrl/Cmd+Enter saves the edit modal. | E11: main.js · keydown handler | F11: Existing | G11: Done | H11: No | I11: Not Tested | J11: 3279
A12: 8 | B12: System (MRI PMX) View | C12: Process/sub card grid | D12: Columns of process and sub-process cards for the active MRI module. | E12: grid.js | F12: Existing | G12: Done | H12: Yes | I12: Pass | J12: 3218, 3228 | K12: Tested and closed 15 Sept 2026.
A13: 9 | B13: System (MRI PMX) View | C13: MRI module reference | D13: Panel shows the MRI navigation path (mri_title) for the process. | E13: panel.js | F13: Existing | G13: Done | H13: No | I13: Not Tested | J13: 3229
A14: 10 | B14: System (MRI PMX) View | C14: Setup prerequisites | D14: Panel lists MRI configuration that must exist before the process can run (mri_prereqs). | E14: panel.js | F14: Existing | G14: Done | H14: No | I14: Not Tested | J14: 3229
A15: 11 | B15: System (MRI PMX) View | C15: Associated MRI screens | D15: Panel lists supporting MRI screens with per-screen descriptions (mri_assoc). | E15: panel.js | F15: Existing | G15: Done | H15: No | I15: Not Tested | J15: 3229
A16: 12 | B16: System (MRI PMX) View | C16: Core activities & overview | D16: Business description and the activities a person performs for each process. | E16: panel.js | F16: Existing | G16: Done | H16: No | I16: Not Tested | J16: 3217, 3229
A17: 13 | B17: System (MRI PMX) View | C17: 9 built-in MRI modules | D17: CM, GL, AP, RM, Job Cost, Corporate AR, Budgeting & Forecasting, Investment Accounting, Fixed Asset Accounting. | E17: data/index.js | F17: Existing | G17: Done | H17: Yes | I17: Pass | J17: 3228 | K17: Tested and closed 15 Sept 2026.
A18: 14 | B18: Business Process View | C18: CRE value-stream taxonomy | D18: Business view organised as Level-1 value streams → Level-2 groups → Level-3 process cards. | E18: business/index.js · valueStreams.js | F18: Existing | G18: Done | H18: No | I18: Not Tested | J18: 3221
A19: 15 | B19: Business Process View | C19: Market variation detail | D19: Per-item guidance that differs by market (UK, US, Pan-European), shown for the selected markets. | E19: businessView.js · showBusinessPanel() | F19: Existing | G19: Done | H19: No | I19: Not Tested | J19: 3223
A20: 16 | B20: Business Process View | C20: Vertical / sector detail | D20: Colour-tagged per-sector guidance (Retail, Industrial, Office, Residential). | E20: businessView.js | F20: Existing | G20: Done | H20: No | I20: Not Tested | J20: 3224
A21: 17 | B21: Business Process View | C21: Standards & frameworks chips | D21: Regulatory/standards tags on cards and in the panel signal compliance weight. | E21: businessView.js | F21: Existing | G21: Done | H21: No | I21: Not Tested | J21: 3225
A22: 18 | B22: Business Process View | C22: Market filter | D22: Multi-select filter drives which market-variation blocks appear in the panel. | E22: businessView.js · renderBusinessFilters() | F22: Existing | G22: Done | H22: No | I22: Not Tested | J22: 3226
A23: 19 | B23: Business Process View | C23: Vertical filter | D23: Multi-select filter hides cards not relevant to the chosen sectors. | E23: businessView.js · matchesVerticals() | F23: Existing | G23: Done | H23: No | I23: Not Tested | J23: 3227
A24: 20 | B24: Business Process View | C24: System-coverage filter | D24: Filter cards by coverage tag (Full / Partial / Outside / Untagged). | E24: businessView.js · matchesCoverage() | F24: Existing | G24: Done | H24: No | I24: Not Tested | J24: 3241
A25: 21 | B25: Business Process View | C25: Enrichment flag | D25: Cards seeded from the reference guide are flagged as needing Market/Vertical/Standards detail. | E25: business/index.js · needsEnrichment (data flag); businessView.js renders it | F25: Existing | G25: Done | H25: No | I25: Not Tested | J25: 3222
A26: 22 | B26: Business Process View | C26: Value-stream context | D26: Panel shows the parent value stream, its note, and whether it is a supporting stream. | E26: businessView.js | F26: Existing | G26: Done | H26: No | I26: Not Tested | J26: 3221
A27: 23 | B27: Mapping / Coverage View | C27: Coverage matrix | D27: Matrix of business domains (rows) × system modules (columns) with per-cell link counts. | E27: mappingView.js · renderMapping() | F27: Existing | G27: Done | H27: No | I27: Not Tested | J27: 3235
A28: 24 | B28: Mapping / Coverage View | C28: Gap highlighting | D28: Domains with no system links are flagged as unmapped; coverage stats summarise the matrix. | E28: mappingView.js / links.js | F28: Existing | G28: Done | H28: No | I28: Not Tested | J28: 3237
A29: 25 | B29: Mapping / Coverage View | C29: Cell detail (visual flow) | D29: Clicking a cell opens a business→system flow list of the linked process pairs. | E29: mappingView.js · showCell() | F29: Existing | G29: Done | H29: Yes | I29: Pass | J29: 3236 | K29: Tested 2026-08-18
A30: 26 | B30: Mapping / Coverage View | C30: Coverage colour coding | D30: Cells and chips colour-coded by coverage (Full / Partial / Outside; mixed shown distinctly). | E30: mappingView.js · cellCoverage() | F30: Existing | G30: Done | H30: No | I30: Not Tested | J30: 3235, 3239
A31: 27 | B31: Mapping / Coverage View | C31: Click-through navigation | D31: From a cell flow, jump straight to the business or system item in its own view. | E31: mappingView.js / main.js · navigateToLinked() | F31: Existing | G31: Done | H31: Yes | I31: Pass | J31: 3232, 3236 | K31: Tested 2026-08-18
A32: 28 | B32: Edit Mode | C32: Toggle edit mode | D32: Enter/exit Edit Mode to reveal add/remove/edit controls across the grid. | E32: main.js · toggleEdit() | F32: Existing | G32: Done | H32: No | I32: Not Tested | J32: 3247, 3248
A33: 29 | B33: Edit Mode | C33: Add column / domain | D33: Add a new column (System) or domain (Business). | E33: addModal.js / businessView.js | F33: Existing | G33: Done | H33: No | I33: Not Tested | J33: 3247, 3248
A34: 30 | B34: Edit Mode | C34: Add process / sub-process | D34: Add processes and sub-processes inline; new items open for editing. | E34: addModal.js / businessView.js | F34: Existing | G34: Done | H34: No | I34: Not Tested | J34: 3247, 3248
A35: 31 | B35: Edit Mode | C35: Edit any item field | D35: In-place modal edits title, description, activities, MRI fields, and client note. | E35: editModal.js / businessEditModal.js | F35: Existing | G35: Done | H35: No | I35: Not Tested | J35: 3247, 3248
A36: 32 | B36: Edit Mode | C36: Remove items | D36: Delete columns, processes, and sub-processes (with undo). | E36: main.js · removeItem() / businessRemove() | F36: Existing | G36: Done | H36: No | I36: Not Tested | J36: 3247, 3248
A37: 33 | B37: Edit Mode | C37: Add custom module tab | D37: Create a new custom module tab with its own name, icon, and header colour. | E37: addModal.js · confirmAddTab() | F37: Existing | G37: Done | H37: No | I37: Not Tested | J37: 3276
A38: 34 | B38: Scope & Coverage Tagging | C38: Scope tags (System) | D38: Tag each item Core / Custom / Out-of-Scope by cycling; drives filtering and export. | E38: main.js · cycleScope() | F38: Existing | G38: Done | H38: No | I38: Not Tested | J38: 3243
A39: 35 | B39: Scope & Coverage Tagging | C39: Bulk-tag column scope | D39: Set scope for every process/sub in a column at once. | E39: main.js · bulkTagColumn() | F39: Existing | G39: Done | H39: No | I39: Not Tested | J39: 3245
A40: 36 | B40: Scope & Coverage Tagging | C40: Scope filter (System) | D40: Multi-select filter shows only selected scopes (Core/Custom/OOS/Untagged). | E40: main.js · renderScopeFilter() | F40: Existing | G40: Done | H40: No | I40: Not Tested | J40: 3246
A41: 37 | B41: Scope & Coverage Tagging | C41: Auto out-of-scope | D41: Items not linked to any value stream can be treated as auto out-of-scope. | E41: grid.js · effectiveScope() | F41: Existing | G41: Done | H41: No | I41: Not Tested | J41: 3244
...

Sheet Comparison
A1: DevOps Backlog ⇄ App Feature Comparison
A2: Board export 2026-09-15: 60 user stories, 224 story points — 8 Pending Feedback, 22 Resolved, 1 Active, 1 Development, 9 Closed, 1 Testing, 4 Analysis, 14 New. 46 of 60 progressed beyond New; 99 of 224 pts Resolved/Closed. 2 stories still read "New" although the tracker records them built. 4 app features have no story (Feature List #83-#86).
A3: A · Matched — board story ↔ existing feature
A4: DevOps ID | B4: Story title | C4: MoSCoW | D4: Board state | E4: Pts | F4: Matched feature(s) | G4: Actual (in code) | H4: Notes / discrepancy
A5: 3216 | B5: Switch between the three engagement views | C5: Must | D5: Pending Feedback | E5: 3 | F5: Three top-level views | G5: Done (in code)
A6: 3217 | B6: Open a detail panel for any card | C6: Must | D6: Resolved | E6: 2 | F6: Detail panel; Core activities & overview | G6: Done (in code)
A7: 3218 | B7: Browse the Tab-Column-Card hierarchy | C7: Must | D7: Pending Feedback | E7: 2 | F7: Process/sub card grid; Module tab bar | G7: Done (in code)
A8: 3219 | B8: Expand and collapse sub-processes | C8: Should | D8: Development | E8: 3 | F8: Expand / collapse sub-processes | G8: Done (in code)
A9: 3221 | B9: Browse CRE value streams | C9: Must | D9: Resolved | E9: 3 | F9: CRE value-stream taxonomy; Value-stream tab bar | G9: Done (in code)
A10: 3222 | B10: See which cards still need enrichment | C10: Should | D10: Analysis | E10: 2 | F10: Enrichment flag | G10: Done (in code)
A11: 3223 | B11: View market variation for a process | C11: Should | D11: Analysis | E11: 3 | F11: Market variation detail | G11: Done (in code)
A12: 3224 | B12: View vertical/sector detail for a process | C12: Should | D12: Pending Feedback | E12: 3 | F12: Vertical / sector detail | G12: Done (in code)
A13: 3225 | B13: See standards and frameworks on a process | C13: Could | D13: Pending Feedback | E13: 2 | F13: Standards & frameworks chips | G13: Done (in code)
A14: 3226 | B14: Filter value streams by market | C14: Should | D14: Pending Feedback | E14: 2 | F14: Market filter | G14: Done (in code)
A15: 3227 | B15: Filter value streams by vertical | C15: Should | D15: Pending Feedback | E15: 2 | F15: Vertical filter | G15: Done (in code)
A16: 3228 | B16: Browse the MRI PMX system taxonomy | C16: Must | D16: Resolved | E16: 3 | F16: Process/sub card grid; 9 built-in MRI modules | G16: Done (in code)
A17: 3229 | B17: See MRI setup detail for a system process | C17: Must | D17: Resolved | E17: 3 | F17: MRI module reference; Setup prerequisites; Associated screens | G17: Done (in code)
A18: 3231 | B18: See linked counterparts in both directions | C18: Must | D18: Closed | E18: 3 | F18: Panel cross-references | G18: Done (in code) | H18: Board Closed as at 2026-09-15; implemented in code.
A19: 3232 | B19: Navigate to a linked counterpart | C19: Must | D19: Closed | E19: 3 | F19: Click-through navigation | G19: Done (in code) | H19: Board Closed as at 2026-09-15; implemented in code.
A20: 3233 | B20: Add a link in Edit Mode | C20: Must | D20: Closed | E20: 5 | F20: Inline link editor; Add-link drill-down combobox | G20: Done (in code) | H20: Board Closed as at 2026-09-15; implemented in code.
A21: 3234 | B21: Remove a link in Edit Mode | C21: Must | D21: Closed | E21: 3 | F21: Inline link editor (remove) | G21: Done (in code) | H21: Board Closed as at 2026-09-15; implemented in code.
A22: 3235 | B22: View the coverage mapping matrix | C22: Should | D22: Resolved | E22: 5 | F22: Coverage matrix; Coverage colour coding | G22: Done (in code)
A23: 3236 | B23: Drill into a matrix cell | C23: Should | D23: Closed | E23: 3 | F23: Cell detail (visual flow) | G23: Done (in code)
A24: 3237 | B24: Identify coverage gaps | C24: Should | D24: Resolved | E24: 3 | F24: Gap highlighting | G24: Done (in code)
A25: 3238 | B25: Tag a value-stream process with system coverage | C25: Must | D25: Resolved | E25: 3 | F25: Coverage tags (Business) | G25: Done (in code)
A26: 3239 | B26: See context for a coverage tag on hover | C26: Should | D26: New | E26: 2 | F26: Coverage colour coding (coverageTooltip) | G26: Done (in code) | H26: Tooltip exists in code (coverageTooltip); feature #26 Done. Board still New as at 2026-09-15 — needs moving.
A27: 3240 | B27: Be warned when a covered process is unlinked | C27: Must | D27: Resolved | E27: 3 | F27: Missing-link warning | G27: Done (in code)
A28: 3241 | B28: Filter value streams by system coverage | C28: Should | D28: Resolved | E28: 3 | F28: System-coverage filter | G28: Done (in code)
A29: 3242 | B29: Bulk-tag a column's coverage | C29: Could | D29: Resolved | E29: 3 | F29: Coverage tags (Business) — bulk per domain | G29: Done (in code)
A30: 3243 | B30: Tag a system process's scope | C30: Should | D30: Pending Feedback | E30: 3 | F30: Scope tags (System) | G30: Done (in code)
A31: 3244 | B31: Auto-derive out-of-scope for unlinked processes | C31: Should | D31: New | E31: 5 | F31: Auto out-of-scope | G31: Done (in code) | H31: Feature #37 Done (grid.js · effectiveScope). Board still New as at 2026-09-15 — needs moving.
A32: 3245 | B32: Bulk-tag a system column's scope | C32: Could | D32: Resolved | E32: 3 | F32: Bulk-tag column scope | G32: Done (in code)
A33: 3246 | B33: Filter the system view by scope | C33: Should | D33: Resolved | E33: 3 | F33: Scope filter (System) | G33: Done (in code)
A34: 3247 | B34: Add, edit and remove business items | C34: Must | D34: Resolved | E34: 5 | F34: Add / Edit / Remove items (business) | G34: Done (in code)
A35: 3248 | B35: Add, edit and remove system items | C35: Must | D35: Analysis | E35: 5 | F35: Add / Edit / Remove items (system) | G35: Done (in code)
A36: 3249 | B36: Capture a client note on an item | C36: Should | D36: Resolved | E36: 3 | F36: Client notes | G36: Done (in code)
A37: 3250 | B37: Save a named client version | C37: Must | D37: Resolved | E37: 5 | F37: Save named versions; Full-state snapshots | G37: Done (in code)
A38: 3251 | B38: Load, rename and delete versions | C38: Must | D38: Closed | E38: 3 | F38: Load / rename / delete versions | G38: Done (in code)
A39: 3252 | B39: Undo recent changes | C39: Should | D39: Resolved | E39: 3 | F39: Undo (up to 20 steps) | G39: Done (in code)
A40: 3253 | B40: Reset to original content | C40: Could | D40: Resolved | E40: 2 | F40: Reset current tab; Reset all | G40: Done (in code)
...

Sheet Summary
A1: Feature & QA Summary
A3: Development Status
A4: Dev Status | B4: Count | C4: % of total
A5: Done | B5: =COUNTIF('Feature List'!$G$5:$G$200,"Done") | C5: =IF(COUNTA('Feature List'!$G$5:$G$200)=0,0,COUNTIF('Feature List'!$G$5:$G$200,"Done")/COUNTA('Feature List'!$G$5:$G$200))
A6: In Progress | B6: =COUNTIF('Feature List'!$G$5:$G$200,"In Progress") | C6: =IF(COUNTA('Feature List'!$G$5:$G$200)=0,0,COUNTIF('Feature List'!$G$5:$G$200,"In Progress")/COUNTA('Feature List'!$G$5:$G$200))
A7: Not Started | B7: =COUNTIF('Feature List'!$G$5:$G$200,"Not Started") | C7: =IF(COUNTA('Feature List'!$G$5:$G$200)=0,0,COUNTIF('Feature List'!$G$5:$G$200,"Not Started")/COUNTA('Feature List'!$G$5:$G$200))
A8: Backlog | B8: =COUNTIF('Feature List'!$G$5:$G$200,"Backlog") | C8: =IF(COUNTA('Feature List'!$G$5:$G$200)=0,0,COUNTIF('Feature List'!$G$5:$G$200,"Backlog")/COUNTA('Feature List'!$G$5:$G$200))
A9: Blocked | B9: =COUNTIF('Feature List'!$G$5:$G$200,"Blocked") | C9: =IF(COUNTA('Feature List'!$G$5:$G$200)=0,0,COUNTIF('Feature List'!$G$5:$G$200,"Blocked")/COUNTA('Feature List'!$G$5:$G$200))
A10: Total | B10: =COUNTA('Feature List'!$G$5:$G$200) | C10: =IF(COUNTA('Feature List'!$G$5:$G$200)=0,0,1)
A12: QA Status
A13: QA Status | B13: Count | C13: % of total
A14: Not Tested | B14: =COUNTIF('Feature List'!$I$5:$I$200,"Not Tested") | C14: =IF(COUNTA('Feature List'!$I$5:$I$200)=0,0,COUNTIF('Feature List'!$I$5:$I$200,"Not Tested")/COUNTA('Feature List'!$I$5:$I$200))
A15: In Progress | B15: =COUNTIF('Feature List'!$I$5:$I$200,"In Progress") | C15: =IF(COUNTA('Feature List'!$I$5:$I$200)=0,0,COUNTIF('Feature List'!$I$5:$I$200,"In Progress")/COUNTA('Feature List'!$I$5:$I$200))
A16: Pass | B16: =COUNTIF('Feature List'!$I$5:$I$200,"Pass") | C16: =IF(COUNTA('Feature List'!$I$5:$I$200)=0,0,COUNTIF('Feature List'!$I$5:$I$200,"Pass")/COUNTA('Feature List'!$I$5:$I$200))
A17: Failed | B17: =COUNTIF('Feature List'!$I$5:$I$200,"Failed") | C17: =IF(COUNTA('Feature List'!$I$5:$I$200)=0,0,COUNTIF('Feature List'!$I$5:$I$200,"Failed")/COUNTA('Feature List'!$I$5:$I$200))
A18: Blocked | B18: =COUNTIF('Feature List'!$I$5:$I$200,"Blocked") | C18: =IF(COUNTA('Feature List'!$I$5:$I$200)=0,0,COUNTIF('Feature List'!$I$5:$I$200,"Blocked")/COUNTA('Feature List'!$I$5:$I$200))
A19: Total | B19: =COUNTA('Feature List'!$I$5:$I$200) | C19: =IF(COUNTA('Feature List'!$I$5:$I$200)=0,0,1)
A21: Source
A22: Source | B22: Count | C22: % of total
A23: Existing | B23: =COUNTIF('Feature List'!$F$5:$F$200,"Existing") | C23: =IF(COUNTA('Feature List'!$F$5:$F$200)=0,0,COUNTIF('Feature List'!$F$5:$F$200,"Existing")/COUNTA('Feature List'!$F$5:$F$200))
A24: DevOps Backlog | B24: =COUNTIF('Feature List'!$F$5:$F$200,"DevOps Backlog") | C24: =IF(COUNTA('Feature List'!$F$5:$F$200)=0,0,COUNTIF('Feature List'!$F$5:$F$200,"DevOps Backlog")/COUNTA('Feature List'!$F$5:$F$200))
A25: New Requirement | B25: =COUNTIF('Feature List'!$F$5:$F$200,"New Requirement") | C25: =IF(COUNTA('Feature List'!$F$5:$F$200)=0,0,COUNTIF('Feature List'!$F$5:$F$200,"New Requirement")/COUNTA('Feature List'!$F$5:$F$200))
A26: Nice to Have | B26: =COUNTIF('Feature List'!$F$5:$F$200,"Nice to Have") | C26: =IF(COUNTA('Feature List'!$F$5:$F$200)=0,0,COUNTIF('Feature List'!$F$5:$F$200,"Nice to Have")/COUNTA('Feature List'!$F$5:$F$200))
A27: Total | B27: =COUNTA('Feature List'!$F$5:$F$200) | C27: =IF(COUNTA('Feature List'!$F$5:$F$200)=0,0,1)
A28: Backlog Comparison
A29: Board stories total | B29: 60
A30: Matched to a tracker feature | B30: 60
A31: On board only (section B) | B31: 4
A32: In app only (no story) | B32: 4
A33: New requirements still to raise | B33: 0
A34: Board "New" but built in code | B34: 2

Sheet Status Key
A1: Status Key — allowed values
A3: Column | B3: Allowed values & meaning
A4: Source | B4: Existing = already in the app (source-derived baseline). DevOps Backlog = folded in from the board. New Requirement = raised during review. Nice to Have = future enhancement.
A5: Dev Status | B5: Done = built in the codebase. In Progress = under active development (board Active/Development, or partially built). Not Started / Backlog = planned only. Blocked = cannot proceed.
A6: Tested? | B6: Yes = QA complete. No = not yet tested. Partial = some testing done. N/A = no QA needed.
A7: QA Status | B7: Not Tested · In Progress · Pass · Failed · Blocked — the outcome/progress of QA.
A8: DevOps Ref | B8: Matched Azure DevOps story ID(s). Multiple IDs = feature spans several stories.
A9: QA Notes | B9: Free text — discrepancies, defects, evidence links, tester, or context.
A10: Comparison sheet | B10: A = matched (board story ↔ feature); B = on board only; C = previously app-only, now has a story; D = new requirements added to the board; E = nice-to-have stories. "Actual (in code)" = what the source actually does, vs the board state. "Board state" and "Pts" come from the latest DevOps export (2026-09-15).
